[32mINFO    [0m test_sign_in_password:test_E2E.py:24 Testcase: Sign in with Password
[32mINFO    [0m test_practicechapters:test_E2E.py:260 Test case: Clicking on Practice Chapter in Practice Home
[32mINFO    [0m test_practicechapters:test_E2E.py:261 Test case: Practice Now Button is displayed in the Practice Summary
[32mINFO    [0m test_practicechapters:test_E2E.py:262 Test case: User is navigated to Practice Taking Screen on clicking on Practice Now button
[33mWARNING [0m urllib3.connectionpool:connectionpool.py:870 Retrying (Retry(total=2, connect=None, read=None, redirect=None, status=None)) after connection broken by 'NewConnectionError('<urllib3.connection.HTTPConnection object at 0x103667690>: Failed to establish a new connection: [Errno 61] Connection refused')': /session/234deb993129b974f54739a29035df80/screenshot
[33mWARNING [0m urllib3.connectionpool:connectionpool.py:870 Retrying (Retry(total=1, connect=None, read=None, redirect=None, status=None)) after connection broken by 'NewConnectionError('<urllib3.connection.HTTPConnection object at 0x103664bd0>: Failed to establish a new connection: [Errno 61] Connection refused')': /session/234deb993129b974f54739a29035df80/screenshot
[33mWARNING [0m urllib3.connectionpool:connectionpool.py:870 Retrying (Retry(total=0, connect=None, read=None, redirect=None, status=None)) after connection broken by 'NewConnectionError('<urllib3.connection.HTTPConnection object at 0x103665390>: Failed to establish a new connection: [Errno 61] Connection refused')': /session/234deb993129b974f54739a29035df80/screenshot
[33mWARNING [0m urllib3.connectionpool:connectionpool.py:870 Retrying (Retry(total=2, connect=None, read=None, redirect=None, status=None)) after connection broken by 'NewConnectionError('<urllib3.connection.HTTPConnection object at 0x1036ce050>: Failed to establish a new connection: [Errno 61] Connection refused')': /session/234deb993129b974f54739a29035df80
[33mWARNING [0m urllib3.connectionpool:connectionpool.py:870 Retrying (Retry(total=1, connect=None, read=None, redirect=None, status=None)) after connection broken by 'NewConnectionError('<urllib3.connection.HTTPConnection object at 0x1036cd1d0>: Failed to establish a new connection: [Errno 61] Connection refused')': /session/234deb993129b974f54739a29035df80
[33mWARNING [0m urllib3.connectionpool:connectionpool.py:870 Retrying (Retry(total=0, connect=None, read=None, redirect=None, status=None)) after connection broken by 'NewConnectionError('<urllib3.connection.HTTPConnection object at 0x1036ccd10>: Failed to establish a new connection: [Errno 61] Connection refused')': /session/234deb993129b974f54739a29035df80