[32mINFO    [0m test_sign_in_password:test_E2E.py:24 Testcase: Sign in with Password
[33mWARNING [0m urllib3.connectionpool:connectionpool.py:870 Retrying (Retry(total=2, connect=None, read=None, redirect=None, status=None)) after connection broken by 'NewConnectionError('<urllib3.connection.HTTPConnection object at 0x105a05090>: Failed to establish a new connection: [Errno 61] Connection refused')': /session/f9cf1afa0ff853e59daf9feba2b0dd9c
[33mWARNING [0m urllib3.connectionpool:connectionpool.py:870 Retrying (Retry(total=1, connect=None, read=None, redirect=None, status=None)) after connection broken by 'NewConnectionError('<urllib3.connection.HTTPConnection object at 0x105a057d0>: Failed to establish a new connection: [Errno 61] Connection refused')': /session/f9cf1afa0ff853e59daf9feba2b0dd9c
[33mWARNING [0m urllib3.connectionpool:connectionpool.py:870 Retrying (Retry(total=0, connect=None, read=None, redirect=None, status=None)) after connection broken by 'NewConnectionError('<urllib3.connection.HTTPConnection object at 0x105a05ed0>: Failed to establish a new connection: [Errno 61] Connection refused')': /session/f9cf1afa0ff853e59daf9feba2b0dd9c